Workbook

Sheet Performance Mail
R1: 17
R2: 31
D5: Performance Sheep Aug 26
D6: Data 1 - 17 Aug 2026 | G6: =SUM(G8:G10) -> 3049305.8 | H6: =SUM(H8:H10) -> 2776 | I6: =SUM(I8:I10) -> 1739236.5 | J6: =I6/G6 -> 0.57037131 | K6: =SUM(K8:K10) -> 3171549 | L6: =SUM(L8:L10) -> 2511632.8 | M6: =K6/G6 -> 1.0400889 | N6: =(K6-L6)/L6 -> 0.26274393
F7: Regional | G7: Target | H7: QTY | I7: Net Amount | J7: % Ach | K7: RR Net Amount | L7: Jul | M7: % RR Ach | N7: %MOM
F8: BMA | G8: =SUMIF($E$14:$E$28,F8,G$14:G$28) -> 1512743.2 | H8: =SUMIF($E$14:$E$28,F8,H$14:H$28) -> 1597 | I8: =SUMIF($E$14:$E$28,F8,I$14:I$28) -> 912308.3 | J8: =I8/G8 -> 0.60308208 | K8: =SUMIF($E$14:$E$28,F8,K$14:K$28) -> 1663621 | L8: =SUMIF($E$14:$E$28,F8,L$14:L$28) -> 1357173.7 | M8: =K8/G8 -> 1.0997379 | N8: =(K8-L8)/L8 -> 0.22579816
F9: UPC I | G9: =SUMIF($E$14:$E$28,F9,G$14:G$28) -> 625961.26 | H9: =SUMIF($E$14:$E$28,F9,H$14:H$28) -> 453 | I9: =SUMIF($E$14:$E$28,F9,I$14:I$28) -> 315025.25 | J9: =I9/G9 -> 0.50326637 | K9: =SUMIF($E$14:$E$28,F9,K$14:K$28) -> 574457.81 | L9: =SUMIF($E$14:$E$28,F9,L$14:L$28) -> 422407.3 | M9: =K9/G9 -> 0.91772102 | N9: =(K9-L9)/L9 -> 0.35996184
F10: UPC II | G10: =SUMIF($E$14:$E$28,F10,G$14:G$28) -> 910601.36 | H10: =SUMIF($E$14:$E$28,F10,H$14:H$28) -> 726 | I10: =SUMIF($E$14:$E$28,F10,I$14:I$28) -> 511903 | J10: =I10/G10 -> 0.56215927 | K10: =SUMIF($E$14:$E$28,F10,K$14:K$28) -> 933470.18 | L10: =SUMIF($E$14:$E$28,F10,L$14:L$28) -> 732051.75 | M10: =K10/G10 -> 1.025114 | N10: =(K10-L10)/L10 -> 0.27514233
G12: =SUM(G14:G28) -> 3049305.8 | H12: =SUM(H14:H28) -> 2776 | I12: =SUM(I14:I28) -> 1739236.5 | J12: =I12/G12 -> 0.57037131 | K12: =SUM(K14:K28) -> 3171549 | L12: =SUM(L14:L28) -> 2511632.8 | M12: =K12/G12 -> 1.0400889 | N12: =(K12-L12)/L12 -> 0.26274393
F13: Area | G13: Target | H13: QTY | I13: Net Amount | J13: % Ach | K13: RR Net Amount | L13: Jul | M13: % RR Ach | N13: %MOM
E14: BMA | F14: BMA I - North West | G14: =SUMIF($F$33:$F$130,F14,G$33:G$130) -> 343719.15 | H14: =SUMIF($F$33:$F$130,F14,H$33:H$130) -> 285 | I14: =SUMIF($F$33:$F$130,F14,I$33:I$130) -> 185333.45 | J14: =I14/G14 -> 0.53920025 | K14: =SUMIF($F$33:$F$130,F14,K$33:K$130) -> 337961 | L14: =SUMIF($F$33:$F$133,F14,L$33:L$133) -> 245427.25 | M14: =K14/G14 -> 0.98324752 | N14: =(K14-L14)/L14 -> 0.37703127
E15: BMA | F15: BMA II - South West | G15: =SUMIF($F$33:$F$130,F15,G$33:G$130) -> 226470.91 | H15: =SUMIF($F$33:$F$130,F15,H$33:H$130) -> 160 | I15: =SUMIF($F$33:$F$130,F15,I$33:I$130) -> 95289.05 | J15: =I15/G15 -> 0.42075625 | K15: =SUMIF($F$33:$F$130,F15,K$33:K$130) -> 173762.39 | L15: =SUMIF($F$33:$F$133,F15,L$33:L$133) -> 140050.15 | M15: =K15/G15 -> 0.76726139 | N15: =(K15-L15)/L15 -> 0.24071545
E16: BMA | F16: BMA III - North East | G16: =SUMIF($F$33:$F$130,F16,G$33:G$130) -> 234942.4 | H16: =SUMIF($F$33:$F$130,F16,H$33:H$130) -> 357 | I16: =SUMIF($F$33:$F$130,F16,I$33:I$130) -> 200966.25 | J16: =I16/G16 -> 0.85538519 | K16: =SUMIF($F$33:$F$130,F16,K$33:K$130) -> 366467.87 | L16: =SUMIF($F$33:$F$133,F16,L$33:L$133) -> 252371 | M16: =K16/G16 -> 1.5598201 | N16: =(K16-L16)/L16 -> 0.45209976
E17: BMA | F17: BMA IV - South East | G17: =SUMIF($F$33:$F$130,F17,G$33:G$130) -> 225274.17 | H17: =SUMIF($F$33:$F$130,F17,H$33:H$130) -> 224 | I17: =SUMIF($F$33:$F$130,F17,I$33:I$130) -> 140351.1 | J17: =I17/G17 -> 0.62302349 | K17: =SUMIF($F$33:$F$130,F17,K$33:K$130) -> 255934.36 | L17: =SUMIF($F$33:$F$133,F17,L$33:L$133) -> 190526 | M17: =K17/G17 -> 1.1361017 | N17: =(K17-L17)/L17 -> 0.34330411
E18: BMA | F18: BMA V - Central | G18: =SUMIF($F$33:$F$130,F18,G$33:G$130) -> 482336.55 | H18: =SUMIF($F$33:$F$130,F18,H$33:H$130) -> 571 | I18: =SUMIF($F$33:$F$130,F18,I$33:I$130) -> 290368.45 | J18: =I18/G18 -> 0.60200383 | K18: =SUMIF($F$33:$F$130,F18,K$33:K$130) -> 529495.41 | L18: =SUMIF($F$33:$F$133,F18,L$33:L$133) -> 528799.3 | M18: =K18/G18 -> 1.0977717 | N18: =(K18-L18)/L18 -> 0.0013163951
E19: UPC II | F19: UPC - Central | G19: =SUMIF($F$33:$F$130,F19,G$33:G$130) -> 174261.65 | H19: =SUMIF($F$33:$F$130,F19,H$33:H$130) -> 88 | I19: =SUMIF($F$33:$F$130,F19,I$33:I$130) -> 65524 | J19: =I19/G19 -> 0.3760093 | K19: =SUMIF($F$33:$F$130,F19,K$33:K$130) -> 119484.94 | L19: =SUMIF($F$33:$F$133,F19,L$33:L$133) -> 114381.3 | M19: =K19/G19 -> 0.68566403 | N19: =(K19-L19)/L19 -> 0.044619542
E20: UPC I | F20: UPC - Central Northeast | G20: =SUMIF($F$33:$F$130,F20,G$33:G$130) -> 81007.52 | H20: =SUMIF($F$33:$F$130,F20,H$33:H$130) -> 68 | I20: =SUMIF($F$33:$F$130,F20,I$33:I$130) -> 50718 | J20: =I20/G20 -> 0.62609002 | K20: =SUMIF($F$33:$F$130,F20,K$33:K$130) -> 92485.765 | L20: =SUMIF($F$33:$F$133,F20,L$33:L$133) -> 76846 | M20: =K20/G20 -> 1.1416936 | N20: =(K20-L20)/L20 -> 0.20352087
E21: UPC II | F21: UPC - East | G21: =SUMIF($F$33:$F$130,F21,G$33:G$130) -> 286063.99 | H21: =SUMIF($F$33:$F$130,F21,H$33:H$130) -> 243 | I21: =SUMIF($F$33:$F$130,F21,I$33:I$130) -> 173455.8 | J21: =I21/G21 -> 0.60635314 | K21: =SUMIF($F$33:$F$130,F21,K$33:K$130) -> 316301.75 | L21: =SUMIF($F$33:$F$133,F21,L$33:L$133) -> 266825.75 | M21: =K21/G21 -> 1.1057028 | N21: =(K21-L21)/L21 -> 0.18542439
E22: UPC I | F22: UPC - Lower North | G22: =SUMIF($F$33:$F$130,F22,G$33:G$130) -> 64072.118 | H22: =SUMIF($F$33:$F$130,F22,H$33:H$130) -> 45 | I22: =SUMIF($F$33:$F$130,F22,I$33:I$130) -> 33486 | J22: =I22/G22 -> 0.52262982 | K22: =SUMIF($F$33:$F$130,F22,K$33:K$130) -> 61062.706 | L22: =SUMIF($F$33:$F$133,F22,L$33:L$133) -> 47607.05 | M22: =K22/G22 -> 0.95303086 | N22: =(K22-L22)/L22 -> 0.28263998
E23: UPC I | F23: UPC - Lower Northeast | G23: =SUMIF($F$33:$F$130,F23,G$33:G$130) -> 139447.61 | H23: =SUMIF($F$33:$F$130,F23,H$33:H$130) -> 126 | I23: =SUMIF($F$33:$F$130,F23,I$33:I$130) -> 88344.6 | J23: =I23/G23 -> 0.63353256 | K23: =SUMIF($F$33:$F$130,F23,K$33:K$130) -> 161098.98 | L23: =SUMIF($F$33:$F$133,F23,L$33:L$133) -> 100315.05 | M23: =K23/G23 -> 1.1552653 | N23: =(K23-L23)/L23 -> 0.60593028
E24: UPC II | F24: UPC - Lower South | G24: =SUMIF($F$33:$F$130,F24,G$33:G$130) -> 93205.73 | H24: =SUMIF($F$33:$F$130,F24,H$33:H$130) -> 46 | I24: =SUMIF($F$33:$F$130,F24,I$33:I$130) -> 30894 | J24: =I24/G24 -> 0.33146031 | K24: =SUMIF($F$33:$F$130,F24,K$33:K$130) -> 56336.118 | L24: =SUMIF($F$33:$F$133,F24,L$33:L$133) -> 65320 | M24: =K24/G24 -> 0.60442762 | N24: =(K24-L24)/L24 -> -0.13753647
E25: UPC I | F25: UPC - Upper North | G25: =SUMIF($F$33:$F$130,F25,G$33:G$130) -> 196935.86 | H25: =SUMIF($F$33:$F$130,F25,H$33:H$130) -> 107 | I25: =SUMIF($F$33:$F$130,F25,I$33:I$130) -> 68959 | J25: =I25/G25 -> 0.35015969 | K25: =SUMIF($F$33:$F$130,F25,K$33:K$130) -> 125748.76 | L25: =SUMIF($F$33:$F$133,F25,L$33:L$133) -> 95995 | M25: =K25/G25 -> 0.63852649 | N25: =(K25-L25)/L25 -> 0.30995119
... E28: UPC II | F28: UPC - West | G28: =SUMIF($F$33:$F$130,F28,G$33:G$130) -> 184766.57 | H28: =SUMIF($F$33:$F$130,F28,H$33:H$130) -> 185 | I28: =SUMIF($F$33:$F$130,F28,I$33:I$130) -> 127256.95 | J28: =I28/G28 -> 0.68874446 | K28: =SUMIF($F$33:$F$130,F28,K$33:K$130) -> 232056.79 | L28: =SUMIF($F$33:$F$133,F28,L$33:L$133) -> 140501.5 | M28: =K28/G28 -> 1.2559458 | N28: =(K28-L28)/L28 -> 0.65163213
G31: =SUM(G33:G130) -> 3049305.8 | H31: =SUM(H33:H130) -> 2776 | I31: =SUM(I33:I130) -> 1739236.6 | J31: =I31/G31 -> 0.57037131 | K31: =SUM(K33:K130) -> 3171549 | L31: =SUM(L33:L140) -> 2511632.8 | M31: =K31/G31 -> 1.0400889 | N31: =(K31-L31)/L31 -> 0.26274393
A32: Rank | B32: Regional I | C32: Type Shop | D32: Shop Code | E32: Shop Name | F32: Area | G32: Target | H32: QTY | I32: Net Amount | J32: % Ach | K32: RR Net Amount | L32: Jul | M32: % RR Ach | N32: %MOM
A33: =RANK(J33,J$33:J$127) -> 1 | D33: 80101706 | E33: True Shop Fashion Island (D) | F33: BMA III - North East | G33: 10000 | H33: =IFERROR(VLOOKUP(D33,'PV Sheep mail'!E$4:G$99000,2,0),0) -> 27 | I33: =IFERROR(VLOOKUP(D33,'PV Sheep mail'!E$4:G$99000,3,0),0) -> 16930 | J33: =IFERROR(I33/G33,0) -> 1.693 | K33: =(I33/$R$1)*$R$2 -> 30872.353 | L33: 0 | M33: =IFERROR(K33/G33,0) -> 3.0872353 | N33: =IFERROR((K33-L33)/L33,0) -> 0
A34: =RANK(J34,J$33:J$127) -> 2 | D34: 80101697 | E34: True Shop Central Udon Thani (D) | F34: UPC - Upper Northeast | G34: 10890.788 | H34: =IFERROR(VLOOKUP(D34,'PV Sheep mail'!E$4:G$99000,2,0),0) -> 21 | I34: =IFERROR(VLOOKUP(D34,'PV Sheep mail'!E$4:G$99000,3,0),0) -> 17149 | J34: =IFERROR(I34/G34,0) -> 1.5746335 | K34: =(I34/$R$1)*$R$2 -> 31271.706 | L34: 17207.05 | M34: =IFERROR(K34/G34,0) -> 2.8713905 | N34: =IFERROR((K34-L34)/L34,0) -> 0.81737752
A35: =RANK(J35,J$33:J$127) -> 3 | D35: 80101705 | E35: True Shop Central Plaza Suratthani (D) | F35: UPC - Upper South | G35: 11481.969 | H35: =IFERROR(VLOOKUP(D35,'PV Sheep mail'!E$4:G$99000,2,0),0) -> 21 | I35: =IFERROR(VLOOKUP(D35,'PV Sheep mail'!E$4:G$99000,3,0),0) -> 17008 | J35: =IFERROR(I35/G35,0) -> 1.481279 | K35: =(I35/$R$1)*$R$2 -> 31014.588 | L35: 19620 | M35: =IFERROR(K35/G35,0) -> 2.7011559 | N35: =IFERROR((K35-L35)/L35,0) -> 0.58076393
A36: =RANK(J36,J$33:J$127) -> 4 | D36: 80101693 | E36: True Shop Central Plaza Mahachai (D) | F36: UPC - West | G36: 10000 | H36: =IFERROR(VLOOKUP(D36,'PV Sheep mail'!E$4:G$99000,2,0),0) -> 21 | I36: =IFERROR(VLOOKUP(D36,'PV Sheep mail'!E$4:G$99000,3,0),0) -> 14321.5 | J36: =IFERROR(I36/G36,0) -> 1.43215 | K36: =(I36/$R$1)*$R$2 -> 26115.676 | L36: 10887.5 | M36: =IFERROR(K36/G36,0) -> 2.6115676 | N36: =IFERROR((K36-L36)/L36,0) -> 1.3986844
A37: =RANK(J37,J$33:J$127) -> 5 | D37: 80101712 | E37: True Shop Central Plaza Ubon Ratchathani (D) | F37: UPC - Central Northeast | G37: 10000 | H37: =IFERROR(VLOOKUP(D37,'PV Sheep mail'!E$4:G$99000,2,0),0) -> 18 | I37: =IFERROR(VLOOKUP(D37,'PV Sheep mail'!E$4:G$99000,3,0),0) -> 13320 | J37: =IFERROR(I37/G37,0) -> 1.332 | K37: =(I37/$R$1)*$R$2 -> 24289.412 | L37: 22012 | M37: =IFERROR(K37/G37,0) -> 2.4289412 | N37: =IFERROR((K37-L37)/L37,0) -> 0.10346228
A38: =RANK(J38,J$33:J$127) -> 6 | D38: 80101698 | E38: True Shop Central West Gate (D) | F38: BMA I - North West | G38: 10000 | H38: =IFERROR(VLOOKUP(D38,'PV Sheep mail'!E$4:G$99000,2,0),0) -> 17 | I38: =IFERROR(VLOOKUP(D38,'PV Sheep mail'!E$4:G$99000,3,0),0) -> 11789 | J38: =IFERROR(I38/G38,0) -> 1.1789 | K38: =(I38/$R$1)*$R$2 -> 21497.588 | L38: 0 | M38: =IFERROR(K38/G38,0) -> 2.1497588 | N38: =IFERROR((K38-L38)/L38,0) -> 0
A39: =RANK(J39,J$33:J$127) -> 7 | D39: 80101713 | E39: True Shop Central Northville | F39: BMA I - North West | G39: 20918.786 | H39: =IFERROR(VLOOKUP(D39,'PV Sheep mail'!E$4:G$99000,2,0),0) -> 33 | I39: =IFERROR(VLOOKUP(D39,'PV Sheep mail'!E$4:G$99000,3,0),0) -> 24432.1 | J39: =IFERROR(I39/G39,0) -> 1.1679502 | K39: =(I39/$R$1)*$R$2 -> 44552.653 | L39: 18678 | M39: =IFERROR(K39/G39,0) -> 2.1297916 | N39: =IFERROR((K39-L39)/L39,0) -> 1.385301
A40: =RANK(J40,J$33:J$127) -> 8 | B40: UPC II | C40: Matching | D40: 80101647 | E40: True Shop Central Krabi | F40: UPC - Upper South | G40: 16629.709 | H40: =IFERROR(VLOOKUP(D40,'PV Sheep mail'!E$4:G$99000,2,0),0) -> 28 | I40: =IFERROR(VLOOKUP(D40,'PV Sheep mail'!E$4:G$99000,3,0),0) -> 19291 | J40: =IFERROR(I40/G40,0) -> 1.1600323 | K40: =(I40/$R$1)*$R$2 -> 35177.706 | L40: 17632.05 | M40: =IFERROR(K40/G40,0) -> 2.1153531 | N40: =IFERROR((K40-L40)/L40,0) -> 0.99510017
A41: =RANK(J41,J$33:J$127) -> 9 | B41: BMA | C41: Matching | D41: 80101391 | E41: True Shop Central Chanthaburi | F41: UPC - East | G41: 45000 | H41: =IFERROR(VLOOKUP(D41,'PV Sheep mail'!E$4:G$99000,2,0),0) -> 75 | I41: =IFERROR(VLOOKUP(D41,'PV Sheep mail'!E$4:G$99000,3,0),0) -> 51283.05 | J41: =IFERROR(I41/G41,0) -> 1.1396233 | K41: =(I41/$R$1)*$R$2 -> 93516.15 | L41: 76911 | M41: =IFERROR(K41/G41,0) -> 2.0781367 | N41: =IFERROR((K41-L41)/L41,0) -> 0.21590085
A42: =RANK(J42,J$33:J$127) -> 10 | B42: BMA | C42: Non matching | D42: 80101303 | E42: True Shop Robinson Roi-Et | F42: UPC - Central Northeast | G42: 21248.24 | H42: =IFERROR(VLOOKUP(D42,'PV Sheep mail'!E$4:G$99000,2,0),0) -> 31 | I42: =IFERROR(VLOOKUP(D42,'PV Sheep mail'!E$4:G$99000,3,0),0) -> 22379 | J42: =IFERROR(I42/G42,0) -> 1.0532166 | K42: =(I42/$R$1)*$R$2 -> 40808.765 | L42: 23847 | M42: =IFERROR(K42/G42,0) -> 1.9205715 | N42: =IFERROR((K42-L42)/L42,0) -> 0.71127457
A43: =RANK(J43,J$33:J$127) -> 11 | B43: UPC I | C43: Non Matching | D43: 80101632 | E43: True Shop Lotus's Bangna-trad | F43: BMA IV - South East | G43: 14963.148 | H43: =IFERROR(VLOOKUP(D43,'PV Sheep mail'!E$4:G$99000,2,0),0) -> 33 | I43: =IFERROR(VLOOKUP(D43,'PV Sheep mail'!E$4:G$99000,3,0),0) -> 15023 | J43: =IFERROR(I43/G43,0) -> 1.004 | K43: =(I43/$R$1)*$R$2 -> 27394.882 | L43: 11166 | M43: =IFERROR(K43/G43,0) -> 1.8308234 | N43: =IFERROR((K43-L43)/L43,0) -> 1.4534195
A44: =RANK(J44,J$33:J$127) -> 12 | B44: UPC I | C44: Non matching | D44: 80100925 | E44: True Shop Fashion Island | F44: BMA III - North East | G44: 120000 | H44: =IFERROR(VLOOKUP(D44,'PV Sheep mail'!E$4:G$99000,2,0),0) -> 225 | I44: =IFERROR(VLOOKUP(D44,'PV Sheep mail'!E$4:G$99000,3,0),0) -> 120350.25 | J44: =IFERROR(I44/G44,0) -> 1.0029188 | K44: =(I44/$R$1)*$R$2 -> 219462.22 | L44: 216204 | M44: =IFERROR(K44/G44,0) -> 1.8288518 | N44: =IFERROR((K44-L44)/L44,0) -> 0.015070122
A45: =RANK(J45,J$33:J$127) -> 13 | D45: 80101692 | E45: True Shop Central Nakorn Sithammarat (D) | F45: UPC - Lower South | G45: 10258.88 | H45: =IFERROR(VLOOKUP(D45,'PV Sheep mail'!E$4:G$99000,2,0),0) -> 14 | I45: =IFERROR(VLOOKUP(D45,'PV Sheep mail'!E$4:G$99000,3,0),0) -> 10260 | J45: =IFERROR(I45/G45,0) -> 1.0001092 | K45: =(I45/$R$1)*$R$2 -> 18709.412 | L45: 17866 | M45: =IFERROR(K45/G45,0) -> 1.8237285 | N45: =IFERROR((K45-L45)/L45,0) -> 0.047207644
A46: =RANK(J46,J$33:J$127) -> 14 | D46: 80101691 | E46: True Shop Ayutthaya (D) | F46: UPC - Central | G46: 10000 | H46: =IFERROR(VLOOKUP(D46,'PV Sheep mail'!E$4:G$99000,2,0),0) -> 13 | I46: =IFERROR(VLOOKUP(D46,'PV Sheep mail'!E$4:G$99000,3,0),0) -> 9888 | J46: =IFERROR(I46/G46,0) -> 0.9888 | K46: =(I46/$R$1)*$R$2 -> 18031.059 | L46: 12208 | M46: =IFERROR(K46/G46,0) -> 1.8031059 | N46: =IFERROR((K46-L46)/L46,0) -> 0.47698713
A47: =RANK(J47,J$33:J$127) -> 15 | D47: 80101702 | E47: True Shop Central Plaza Chaengwattana (D) | F47: BMA I - North West | G47: 10000 | H47: =IFERROR(VLOOKUP(D47,'PV Sheep mail'!E$4:G$99000,2,0),0) -> 16 | I47: =IFERROR(VLOOKUP(D47,'PV Sheep mail'!E$4:G$99000,3,0),0) -> 9840 | J47: =IFERROR(I47/G47,0) -> 0.984 | K47: =(I47/$R$1)*$R$2 -> 17943.529 | L47: 3650 | M47: =IFERROR(K47/G47,0) -> 1.7943529 | N47: =IFERROR((K47-L47)/L47,0) -> 3.9160355
...

Sheet PV Sheep mail
E1: วันที่ทำรายการ | F1: (All) | I1: วันที่ทำรายการ | J1: 17/8/2026 | M1: วันที่ทำรายการ | N1: (All)
A3: Row Labels | B3: Sum of จำนวน | C3: Sum of ราคารวม | E3: Row Labels | F3: Sum of จำนวน | G3: Sum of ราคารวม | I3: Row Labels | J3: Sum of จำนวน | K3: Sum of ราคารวม | M3: Row Labels | N3: Sum of จำนวน | O3: Sum of ราคารวม | Q3: Sum of ราคารวม | R3: Column Labels
A4: (blank) | E4: 80100477 | F4: 36 | G4: 24391 | I4: 80100479 | J4: 2 | K4: 1980 | N4: 232 | O4: 137678.75 | Q4: Row Labels | R4: (blank) | S4: 1/8/2026 | T4: 2/8/2026 | U4: 3/8/2026 | V4: 4/8/2026 | W4: 5/8/2026 | X4: 6/8/2026 | Y4: 7/8/2026 | Z4: 8/8/2026 | AA4: 9/8/2026 | AB4: 10/8/2026 | AC4: 11/8/2026 | AD4: 12/8/2026 | AE4: 13/8/2026 | AF4: 14/8/2026 | AG4: 16/8/2026 | AH4: 15/8/2026 | AI4: 17/8/2026 | AJ4: Grand Total
A5: 1/8/2026 | B5: 156 | C5: 106229.3 | E5: 80100479 | F5: 44 | G5: 32451 | I5: 80100480 | J5: 1 | K5: 349 | M5: n | N5: 2 | O5: 690 | Q5: 80100476 | S5: 690 | T5: 690 | V5: 1580 | W5: 1870 | Z5: 890 | AA5: 3230 | AB5: 990 | AD5: 1080 | AE5: 2850 | AF5: 6430 | AG5: 4820 | AH5: 1480 | AI5: 1280 | AJ5: 27880
A6: 2/8/2026 | B6: 170 | C6: 105006.65 | E6: 80100480 | F6: 29 | G6: 17094.3 | I6: 80100483 | J6: 1 | K6: 890 | M6: 010 H2216 | N6: 1 | O6: 690 | Q6: 80100477 | S6: 2160 | T6: 890 | U6: 1480 | V6: 690 | Y6: 590 | AA6: 1780 | AB6: 5330 | AC6: 780 | AD6: 1480 | AE6: 4722 | AF6: 3250 | AH6: 1239 | AJ6: 24391
A7: 3/8/2026 | B7: 129 | C7: 77974.65 | E7: 80100483 | F7: 15 | G7: 11227 | I7: 80100484 | J7: 1 | K7: 349 | M7: 01017152 | N7: 2 | O7: 1780 | Q7: 80100479 | T7: 1680 | U7: 990 | V7: 2870 | W7: 3360 | X7: 1680 | Y7: 990 | Z7: 4018 | AA7: 2768 | AB7: 3268 | AC7: 590 | AD7: 3668 | AE7: 1629 | AF7: 1280 | AG7: 690 | AH7: 990 | AI7: 1980 | AJ7: 32451
A8: 4/8/2026 | B8: 138 | C8: 84483.95 | E8: 80100484 | F8: 34 | G8: 24937 | I8: 80100565 | J8: 3 | K8: 2670 | M8: 01017152 | N8: 1 | O8: 890 | Q8: 80100480 | S8: 890 | W8: 1809.3 | X8: 1480 | Y8: 1480 | Z8: 3170 | AA8: 1616 | AC8: 890 | AD8: 2070 | AE8: 1190 | AF8: 780 | AH8: 1370 | AI8: 349 | AJ8: 17094.3
A9: 5/8/2026 | B9: 129 | C9: 80096.5 | E9: 80100486 | F9: 17 | G9: 12089 | I9: 80100615 | J9: 1 | K9: 349 | M9: 01021762 | N9: 1 | O9: 990 | Q9: 80100481 | S9: 2470 | T9: 890 | U9: 590 | V9: 990 | Y9: 590 | Z9: 1670 | AA9: 1390 | AC9: 4240 | AD9: 980 | AE9: 2260 | AF9: 880 | AG9: 4620 | AH9: 2460 | AI9: 2260 | AJ9: 26290
A10: 6/8/2026 | B10: 141 | C10: 85354.75 | E10: 80100565 | F10: 30 | G10: 20999.05 | I10: 80100621 | J10: 3 | K10: 1370 | M10: 01024322 | N10: 1 | O10: 890 | Q10: 80100483 | S10: 590 | U10: 1980 | Y10: 349 | Z10: 590 | AD10: 1880 | AE10: 890 | AG10: 590 | AH10: 3468 | AI10: 890 | AJ10: 11227
A11: 7/8/2026 | B11: 134 | C11: 82952.3 | E11: 80100615 | F11: 19 | G11: 15669 | I11: 80100623 | J11: 12 | K11: 6513.05 | M11: 01025153 | N11: 4 | O11: 2719 | Q11: 80100484 | S11: 1780 | T11: 3560 | U11: 1780 | V11: 1180 | X11: 590 | AA11: 1770 | AB11: 690 | AC11: 2670 | AD11: 2070 | AE11: 890 | AF11: 349 | AG11: 3999 | AH11: 3260 | AI11: 349 | AJ11: 24937
A12: 8/8/2026 | B12: 208 | C12: 136887.75 | E12: 80100621 | F12: 23 | G12: 13670 | I12: 80100625 | J12: 1 | K12: 890 | M12: 01025153 | N12: 1 | O12: 890 | Q12: 80100486 | T12: 590 | V12: 1080 | AA12: 1180 | AB12: 1880 | AC12: 490 | AD12: 1339 | AF12: 690 | AG12: 2970 | AH12: 1870 | AJ12: 12089
A13: 9/8/2026 | B13: 236 | C13: 146874.95 | E13: 80100623 | F13: 460 | G13: 215893.2 | I13: 80100626 | J13: 1 | K13: 890 | M13: 01026318 | N13: 1 | O13: 890 | Q13: 80100487 | T13: 1280 | V13: 2270 | W13: 1380 | Y13: 1980 | Z13: 1380 | AA13: 2270 | AC13: 990 | AD13: 1189 | AE13: 990 | AH13: 2170 | AI13: 890 | AJ13: 16789
A14: 10/8/2026 | B14: 157 | C14: 81984.6 | E14: 80100625 | F14: 31 | G14: 24708.55 | I14: 80100836 | J14: 1 | K14: 590 | M14: 01026318 | N14: 1 | O14: 349 | Q14: 80100565 | S14: 890 | T14: 2660 | W14: 2029 | X14: 590 | Z14: 1280 | AA14: 2170 | AC14: 1680 | AD14: 590 | AF14: 2078 | AG14: 3672.05 | AH14: 690 | AI14: 2670 | AJ14: 20999.05
A15: 11/8/2026 | B15: 125 | C15: 80051.9 | E15: 80100626 | F15: 56 | G15: 20358 | I15: 80100837 | J15: 1 | K15: 890 | M15: 01026427 | N15: 2 | O15: 1080 | Q15: 80100615 | S15: 1680 | U15: 1780 | V15: 1680 | Z15: 1770 | AC15: 1880 | AD15: 3170 | AE15: 1380 | AF15: 990 | AH15: 990 | AI15: 349 | AJ15: 15669
A16: 12/8/2026 | B16: 228 | C16: 152472.05 | E16: 80100754 | F16: 7 | G16: 5089 | I16: 80100840 | J16: 1 | K16: 890 | M16: 01026587 | N16: 1 | O16: 890 | Q16: 80100621 | S16: 990 | T16: 590 | U16: 1680 | V16: 1960 | X16: 980 | Y16: 690 | Z16: 690 | AA16: 1570 | AB16: 590 | AD16: 490 | AE16: 490 | AF16: 990 | AH16: 590 | AI16: 1370 | AJ16: 13670
A17: 13/8/2026 | B17: 137 | C17: 85375.75 | E17: 80100756 | F17: 10 | G17: 6718 | I17: 80100925 | J17: 7 | K17: 3950 | M17: 01029194 | N17: 5 | O17: 3809 | Q17: 80100622 | Z17: 3758 | AA17: 3740 | AB17: 2670 | AD17: 5040 | AE17: 3162.05 | AF17: 4120 | AH17: 939 | AI17: 4140 | AJ17: 27569.05
A18: 14/8/2026 | B18: 163 | C18: 103040.65 | E18: 80100763 | F18: 4 | G18: 2960 | I18: 80100928 | J18: 4 | K18: 2560 | M18: 01030759 | N18: 1 | O18: 890 | Q18: 80100623 | S18: 13608.05 | T18: 13534.1 | U18: 7760.6 | V18: 11381.65 | W18: 10855.1 | X18: 22471.15 | Y18: 14407.75 | Z18: 17959.55 | AA18: 14069.1 | AB18: 9111.05 | AC18: 8109 | AD18: 9076 | AE18: 12665 | AF18: 14346.1 | AG18: 15008.85 | AH18: 15017.1 | AI18: 6513.05 | AJ18: 215893.2
A19: 16/8/2026 | B19: 205 | C19: 128374.95 | E19: 80100836 | F19: 12 | G19: 8396.1 | I19: 80101067 | J19: 1 | K19: 890 | M19: 01032158 | N19: 2 | O19: 1339 | Q19: 80100625 | S19: 890 | T19: 890 | U19: 590 | V19: 2229 | W19: 890 | Y19: 3591.55 | Z19: 1539 | AA19: 1480 | AB19: 890 | AD19: 1880 | AE19: 1929 | AG19: 3260 | AH19: 3760 | AI19: 890 | AJ19: 24708.55
A20: 15/8/2026 | B20: 208 | C20: 126827.8 | E20: 80100837 | F20: 32 | G20: 22787.2 | I20: 80101068 | J20: 1 | K20: 890 | M20: 01032621 | N20: 1 | O20: 690 | Q20: 80100626 | S20: 890 | U20: 1239 | V20: 590 | Y20: 2129 | Z20: 2070 | AA20: 590 | AB20: 590 | AC20: 890 | AD20: 5340 | AF20: 890 | AG20: 3360 | AH20: 890 | AI20: 890 | AJ20: 20358
A21: 17/8/2026 | B21: 112 | C21: 75248.05 | E21: 80100840 | F21: 55 | G21: 35096.65 | I21: 80101070 | J21: 4 | K21: 2460 | M21: 01032631 | N21: 1 | O21: 690 | Q21: 80100750 | T21: 1470 | U21: 2240 | V21: 490 | X21: 880 | Y21: 2470 | AB21: 990 | AD21: 490 | AE21: 690 | AF21: 590 | AG21: 490 | AI21: 698 | AJ21: 11498
A22: Grand Total | B22: 2776 | C22: 1739236.6 | E22: 80100842 | F22: 6 | G22: 4940 | I22: 80101071 | J22: 1 | K22: 990 | M22: 01032838 | N22: 6 | O22: 3950 | Q22: 80100754 | T22: 1680 | U22: 1480 | Z22: 690 | AB22: 349 | AD22: 890 | AJ22: 5089
E23: 80100925 | F23: 225 | G23: 120350.25 | I23: 80101115 | J23: 1 | K23: 890 | M23: 01033603 | N23: 12 | O23: 7389 | Q23: 80100756 | Y23: 590 | AC23: 1080 | AD23: 2029 | AF23: 1339 | AG23: 1680 | AJ23: 6718
E24: 80100928 | F24: 25 | G24: 17768 | I24: 80101183 | J24: 3 | K24: 2070 | M24: 0103911 | N24: 1 | O24: 290 | Q24: 80100763 | U24: 890 | Z24: 590 | AA24: 890 | AB24: 590 | AJ24: 2960
E25: 80101067 | F25: 11 | G25: 7449 | I25: 80101185 | J25: 1 | K25: 890 | M25: 01040454 | N25: 4 | O25: 2660 | Q25: 80100782 | W25: 490 | AE25: 990 | AH25: 490 | AI25: 1470 | AJ25: 3440
E26: 80101068 | F26: 13 | G26: 9570 | I26: 80101214 | J26: 1 | K26: 690 | M26: 01040503 | N26: 3 | O26: 2370 | Q26: 80100822 | S26: 2891 | T26: 2260 | U26: 880 | W26: 2719 | X26: 2577.05 | AB26: 1221.55 | AC26: 4954.1 | AD26: 2229 | AE26: 4192.55 | AF26: 2760 | AG26: 690 | AI26: 741 | AJ26: 28115.25
E27: 80101070 | F27: 64 | G27: 42760 | I27: 80101263 | J27: 2 | K27: 1680 | M27: 01040516 | N27: 4 | O27: 2635 | Q27: 80100836 | S27: 1290 | W27: 990 | Y27: 1388 | AA27: 1268.1 | AD27: 990 | AE27: 1880 | AI27: 590 | AJ27: 8396.1
E28: 80101071 | F28: 42 | G28: 30831.1 | I28: 80101266 | J28: 1 | K28: 890 | M28: 01042235 | N28: 1 | O28: 590 | Q28: 80100837 | S28: 690 | V28: 890 | W28: 590 | X28: 890 | Y28: 3260 | Z28: 890 | AA28: 2470 | AB28: 1580 | AC28: 4509.2 | AD28: 590 | AE28: 1480 | AF28: 2229 | AH28: 1829 | AI28: 890 | AJ28: 22787.2
E29: 80101115 | F29: 15 | G29: 12450 | I29: 80101303 | J29: 1 | K29: 990 | M29: 01043911 | N29: 6 | O29: 4540 | Q29: 80100838 | U29: 690 | W29: 1489 | X29: 199 | AA29: 690 | AF29: 690 | AH29: 2070 | AJ29: 5828
E30: 80101182 | F30: 13 | G30: 9670 | I30: 80101305 | J30: 5 | K30: 4450 | M30: 01043914 | N30: 9 | O30: 5410 | Q30: 80100839 | T30: 890 | V30: 590 | Y30: 1047 | Z30: 199 | AB30: 890 | AC30: 890 | AD30: 1880 | AG30: 990 | AJ30: 7376
E31: 80101183 | F31: 39 | G31: 24410 | I31: 80101306 | J31: 2 | K31: 1380 | M31: 01044539 | N31: 2 | O31: 1480 | Q31: 80100840 | S31: 890 | T31: 590 | U31: 1026 | V31: 1180 | W31: 890 | Y31: 2960 | Z31: 4330 | AA31: 3340 | AB31: 3260 | AC31: 1280 | AD31: 2716 | AE31: 490 | AF31: 2791 | AG31: 2560 | AH31: 5903.65 | AI31: 890 | AJ31: 35096.65
E32: 80101185 | F32: 54 | G32: 34809.05 | I32: 80101312 | J32: 1 | K32: 990 | M32: 01044539 | N32: 1 | O32: 890 | Q32: 80100841 | U32: 590 | AJ32: 590
E33: 80101186 | F33: 20 | G33: 14000 | I33: 80101340 | J33: 1 | K33: 590 | M33: 01045422 | N33: 1 | O33: 349 | Q33: 80100842 | S33: 890 | W33: 590 | AE33: 990 | AF33: 590 | AG33: 890 | AH33: 990 | AJ33: 4940
E34: 80101189 | F34: 26 | G34: 16158 | I34: 80101391 | J34: 2 | K34: 1280 | M34: 01046318 | N34: 4 | O34: 2660 | Q34: 80100854 | AA34: 1239 | AJ34: 1239
E35: 80101196 | F35: 16 | G35: 12040 | I35: 80100476 | J35: 2 | K35: 1280 | M35: 01046971 | N35: 2 | O35: 1239 | Q35: 80100925 | S35: 16544.2 | T35: 14396.5 | U35: 7211.05 | V35: 7024.15 | W35: 1580 | X35: 6842.55 | Y35: 2681 | Z35: 6692.05 | AA35: 10291.05 | AB35: 1580 | AC35: 890 | AD35: 12461.05 | AE35: 3257.05 | AF35: 4258.55 | AG35: 8900 | AH35: 11791.05 | AI35: 3950 | AJ35: 120350.25
E36: 80101214 | F36: 24 | G36: 18184.65 | I36: 80100487 | J36: 1 | K36: 890 | M36: 01047016 | N36: 1 | O36: 590 | Q36: 80100926 | S36: 4540 | T36: 2770 | V36: 990 | W36: 1480 | Y36: 590 | Z36: 1870 | AA36: 1580 | AD36: 349 | AG36: 2270 | AJ36: 16439
E37: 80101222 | F37: 15 | G37: 8918 | I37: 80101647 | J37: 5 | K37: 3350 | M37: 01047181 | N37: 7 | O37: 4940 | Q37: 80100928 | S37: 1780 | W37: 1380 | Y37: 349 | AA37: 2470 | AC37: 2960 | AD37: 1970 | AE37: 1580 | AF37: 890 | AG37: 1480 | AH37: 349 | AI37: 2560 | AJ37: 17768
E38: 80101263 | F38: 19 | G38: 14726 | I38: 80100782 | J38: 3 | K38: 1470 | M38: 01047197 | N38: 1 | O38: 590 | Q38: 80101067 | U38: 590 | W38: 349 | X38: 1180 | Z38: 690 | AA38: 890 | AE38: 1580 | AF38: 590 | AH38: 690 | AI38: 890 | AJ38: 7449
E39: 80101266 | F39: 14 | G39: 10969 | I39: 80101119 | J39: 2 | K39: 980 | M39: 01047304 | N39: 2 | O39: 398 | Q39: 80101068 | W39: 890 | Z39: 3540 | AA39: 1880 | AG39: 590 | AH39: 1780 | AI39: 890 | AJ39: 9570
E40: 80101303 | F40: 31 | G40: 22379 | I40: 80101584 | J40: 1 | K40: 890 | M40: 01048298 | N40: 1 | O40: 890 | Q40: 80101070 | S40: 1780 | T40: 2360 | U40: 590 | W40: 1780 | X40: 3940 | Y40: 590 | Z40: 6010 | AA40: 6410 | AB40: 890 | AC40: 1880 | AD40: 6310 | AE40: 880 | AF40: 3650 | AG40: 590 | AH40: 2640 | AI40: 2460 | AJ40: 42760
E41: 80101305 | F41: 25 | G41: 14842 | I41: 80100481 | J41: 4 | K41: 2260 | M41: 01049059 | N41: 2 | O41: 1580 | Q41: 80101071 | S41: 1480 | T41: 1580 | U41: 690 | V41: 690 | X41: 1280 | Y41: 3360 | Z41: 6036.05 | AA41: 5337.05 | AC41: 939 | AD41: 290 | AE41: 590 | AF41: 1780 | AG41: 1929 | AH41: 3860 | AI41: 990 | AJ41: 30831.1
...

Sheet Data Mail
A1: รายการ | B1: สร้างโดย | C1: ช่องทางการขาย | D1: วันที่ทำรายการ | E1: ส่วนลด | F1: รายได้จาก Platform | G1: มูลค่ารวมก่อนภาษี | H1: ภาษีมูลค่าเพิ่ม | I1: มูลค่า | J1: หมายเหตุ | K1: สถานะรายการ | L1: คลัง/สาขา | M1: สถานะการชำระเงิน | N1: ใบกำกับภาษี | O1: ช่องทางการชำระเงิน | P1: จำนวนเงินที่ชำระ | Q1: วันที่ชำระเงิน | R1: รหัสสินค้า | S1: ชื่อสินค้า | T1: จำนวน | U1: ราคาต่อหน่วย | V1: ส่วนลดต่อหน่วย | W1: ราคารวม | X1: ล็อต | Y1: หมวดหมู่ | Z1: Shop Code | AA1: Shop Name | AB1: AREA | AC1: Regional
A2: RC-142-202608026 | B2: True Shop Central Pinklao 3Fl. | C2: POS | D2: 17/8/2026 | E2: 0.0 | F2: 0 | G2: 831.78 | H2: 58.22 | I2: 890 | J2: 01017152 | K2: สำเร็จ | L2: True Shop Central Pinklao 3Fl. | M2: ชำระครบ | O2: KBANK | P2: 890 | Q2: 17/8/2026 20:48 | R2: 4IPH172IMM516 | S2: Sheep Canvas 17 Pro - Cinnamoroll | T2: 1 | U2: 990 | V2: 100.0 | W2: 890 | Y2: Sanrio x Sheep | Z2: =VLOOKUP(B2,Sheet1!A$4:F$4000,2,0) -> 80100626 | AA2: =VLOOKUP(B2,Sheet1!A$4:F$4000,3,0) -> True Shop Central Pinklao 3Fl. | AB2: =VLOOKUP(B2,Sheet1!A$4:F$4000,4,0) -> BMA II - South West | AC2: =VLOOKUP(B2,Sheet1!A$4:F$4000,6,0) -> BMA
A3: RC-125-202608211 | B3: TRUE - Central Rama 9 | C3: POS | D3: 17/8/2026 | E3: 0.0 | F3: 0 | G3: 925.23 | H3: 64.77 | I3: 990 | J3: b | K3: สำเร็จ | L3: True Shop Central Rama 9 | M3: ชำระครบ | O3: KBANK | P3: 990 | Q3: 17/8/2026 20:45 | R3: 9IPH173IMM434 | S3: iPhone 17 Pro Max Magsafe - Esther Bunny | T3: 1 | U3: 990 | V3: 0.0 | W3: 990 | Y3: Esther Bunny x Sheep | Z3: =VLOOKUP(B3,Sheet1!A$4:F$4000,2,0) -> 80100623 | AA3: =VLOOKUP(B3,Sheet1!A$4:F$4000,3,0) -> True Shop Central Rama 9 | AB3: =VLOOKUP(B3,Sheet1!A$4:F$4000,4,0) -> BMA V - Central | AC3: =VLOOKUP(B3,Sheet1!A$4:F$4000,6,0) -> BMA
A4: RC-133-202608056 | B4: True Shop Central Chanthaburi | C4: POS | D4: 17/8/2026 | E4: 0.0 | F4: 0 | G4: 1196.26 | H4: 83.74 | I4: 1280 | J4: 1280879 | K4: สำเร็จ | L4: True Shop Central Chanthaburi | M4: ชำระครบ | O4: KBANK | P4: 1280 | Q4: 17/8/2026 20:23 | R4: 5IPH173IMM503 | S4: iPhone 17 Pro Max Magsafe - Stitch Travel | T4: 1 | U4: 990 | V4: 71.74 | W4: 918.26 | Y4: Disney x Sheep | Z4: =VLOOKUP(B4,Sheet1!A$4:F$4000,2,0) -> 80101391 | AA4: =VLOOKUP(B4,Sheet1!A$4:F$4000,3,0) -> True Shop Central Chanthaburi | AB4: =VLOOKUP(B4,Sheet1!A$4:F$4000,4,0) -> UPC - East | AC4: =VLOOKUP(B4,Sheet1!A$4:F$4000,6,0) -> UPC II
A5: RC-133-202608056 | B5: True Shop Central Chanthaburi | C5: POS | D5: 17/8/2026 | J5: 1280879 | K5: สำเร็จ | L5: True Shop Central Chanthaburi | M5: ชำระครบ | R5: 2SCP172BCG004 | S5: Sheep Bullet Camera Glass iPhone 17 Pro /17 Pro Max - Blue | T5: 1 | U5: 390 | V5: 28.26 | W5: 361.74 | Y5: Screen Protector | Z5: =VLOOKUP(B5,Sheet1!A$4:F$4000,2,0) -> 80101391 | AA5: =VLOOKUP(B5,Sheet1!A$4:F$4000,3,0) -> True Shop Central Chanthaburi | AB5: =VLOOKUP(B5,Sheet1!A$4:F$4000,4,0) -> UPC - East | AC5: =VLOOKUP(B5,Sheet1!A$4:F$4000,6,0) -> UPC II
A6: RC-61-202608027 | B6: True Shop Central Rama 2 | C6: POS | D6: 17/8/2026 | E6: 0.0 | F6: 0 | G6: 831.78 | H6: 58.22 | I6: 890 | J6: 12809394 | K6: สำเร็จ | L6: True Shop Central Rama 2 | M6: ชำระครบ | O6: BBL | P6: 890 | Q6: 17/8/2026 20:21 | R6: 4IPH170IMM522 | S6: Sheep Canvas 17 - Little Twin Stars | T6: 1 | U6: 990 | V6: 100.0 | W6: 890 | Y6: Sanrio x Sheep | Z6: =VLOOKUP(B6,Sheet1!A$4:F$4000,2,0) -> 80100565 | AA6: =VLOOKUP(B6,Sheet1!A$4:F$4000,3,0) -> True Shop Central Rama 2 | AB6: =VLOOKUP(B6,Sheet1!A$4:F$4000,4,0) -> BMA II - South West | AC6: =VLOOKUP(B6,Sheet1!A$4:F$4000,6,0) -> BMA
A7: RC-141-202608029 | B7: True Shop The mall Bangkapi | C7: POS | D7: 17/8/2026 | E7: 0.0 | F7: 0 | G7: 551.4 | H7: 38.6 | I7: 590 | J7: 010L6088 | K7: สำเร็จ | L7: True Shop The Mall Bangkapi | M7: ชำระครบ | O7: KBANK | P7: 590 | Q7: 17/8/2026 20:16 | R7: 2IPH173SCM003 | S7: Sheep Canvas Clear Pink - iPhone 17 Pro Max | T7: 1 | U7: 690 | V7: 100.0 | W7: 590 | Y7: Sheep Clear | Z7: =VLOOKUP(B7,Sheet1!A$4:F$4000,2,0) -> 80100481 | AA7: =VLOOKUP(B7,Sheet1!A$4:F$4000,3,0) -> True Shop The Mall Bangkapi | AB7: =VLOOKUP(B7,Sheet1!A$4:F$4000,4,0) -> BMA IV - South East | AC7: =VLOOKUP(B7,Sheet1!A$4:F$4000,6,0) -> BMA
A8: RC-151-202608015 | B8: True Shop Central Plaza Suratthani | C8: POS | D8: 17/8/2026 | E8: 0.0 | F8: 0 | G8: 831.78 | H8: 58.22 | I8: 890 | J8: 12809839 | K8: สำเร็จ | L8: True Shop Central Plaza Suratthani | M8: ชำระครบ | O8: BBL | P8: 890 | Q8: 17/8/2026 20:18 | R8: 5IPH170IMM526 | S8: iPhone 17 Magsafe - Mickey Mouse | T8: 1 | U8: 990 | V8: 100.0 | W8: 890 | Y8: Disney x Sheep | Z8: =VLOOKUP(B8,Sheet1!A$4:F$4000,2,0) -> 80101115 | AA8: =VLOOKUP(B8,Sheet1!A$4:F$4000,3,0) -> True Shop Central Plaza Suratthani | AB8: =VLOOKUP(B8,Sheet1!A$4:F$4000,4,0) -> UPC - Upper South | AC8: =VLOOKUP(B8,Sheet1!A$4:F$4000,6,0) -> UPC II
A9: RC-124-202608128 | B9: TRUE - Fashion Island | C9: POS | D9: 17/8/2026 | E9: 0.0 | F9: 0 | G9: 644.86 | H9: 45.14 | I9: 690 | J9: j | K9: สำเร็จ | L9: True Shop Fashion Island | M9: ชำระครบ | O9: KBANK | P9: 690 | Q9: 17/8/2026 19:58 | R9: 2SIP173SGP013 | S9: Sheep Screen Protector Privacy Glass - iPhone 17 Pro Max | T9: 1 | U9: 690 | V9: 0.0 | W9: 690 | Y9: Screen Protector | Z9: =VLOOKUP(B9,Sheet1!A$4:F$4000,2,0) -> 80100925 | AA9: =VLOOKUP(B9,Sheet1!A$4:F$4000,3,0) -> True Shop Fashion Island | AB9: =VLOOKUP(B9,Sheet1!A$4:F$4000,4,0) -> BMA III - North East | AC9: =VLOOKUP(B9,Sheet1!A$4:F$4000,6,0) -> BMA
A10: RC-42-202608022 | B10: True Shop Robinson Srisaman | C10: POS | D10: 17/8/2026 | E10: 0.0 | F10: 0 | G10: 1205.61 | H10: 84.39 | I10: 1290 | J10: 12808920 | K10: สำเร็จ | L10: True Shop Robinson Srisaman | M10: ชำระครบ | O10: KBANK | P10: 1290 | Q10: 17/8/2026 19:56 | R10: 5IPH173SOF529 | S10: Sheep Outfit 17 Pro Max - Mickey Steamboat | T10: 1 | U10: 1290 | V10: 0.0 | W10: 1290 | Y10: Disney x Sheep | Z10: =VLOOKUP(B10,Sheet1!A$4:F$4000,2,0) -> 80101305 | AA10: =VLOOKUP(B10,Sheet1!A$4:F$4000,3,0) -> True Shop Robinson Sri Saman | AB10: =VLOOKUP(B10,Sheet1!A$4:F$4000,4,0) -> BMA I - North West | AC10: =VLOOKUP(B10,Sheet1!A$4:F$4000,6,0) -> BMA
A11: RC-124-202608127 | B11: TRUE - Fashion Island | C11: POS | D11: 17/8/2026 | E11: 0.0 | F11: 0 | G11: 831.78 | H11: 58.22 | I11: 890 | J11: jp | K11: สำเร็จ | L11: True Shop Fashion Island | M11: ชำระครบ | O11: KBANK | P11: 890 | Q11: 17/8/2026 19:52 | R11: 9IPH170IMM434 | S11: iPhone 17 Magsafe - Esther Bunny | T11: 1 | U11: 990 | V11: 100.0 | W11: 890 | Y11: Esther Bunny x Sheep | Z11: =VLOOKUP(B11,Sheet1!A$4:F$4000,2,0) -> 80100925 | AA11: =VLOOKUP(B11,Sheet1!A$4:F$4000,3,0) -> True Shop Fashion Island | AB11: =VLOOKUP(B11,Sheet1!A$4:F$4000,4,0) -> BMA III - North East | AC11: =VLOOKUP(B11,Sheet1!A$4:F$4000,6,0) -> BMA
A12: RC-42-202608021 | B12: True Shop Robinson Srisaman | C12: POS | D12: 17/8/2026 | E12: 0.0 | F12: 0 | G12: 644.86 | H12: 45.14 | I12: 690 | J12: 12808920 | K12: สำเร็จ | L12: True Shop Robinson Srisaman | M12: ชำระครบ | O12: KBANK | P12: 690 | Q12: 17/8/2026 19:51 | R12: 2SIP173SGP013 | S12: Sheep Screen Protector Privacy Glass - iPhone 17 Pro Max | T12: 1 | U12: 690 | V12: 0.0 | W12: 690 | Y12: Screen Protector | Z12: =VLOOKUP(B12,Sheet1!A$4:F$4000,2,0) -> 80101305 | AA12: =VLOOKUP(B12,Sheet1!A$4:F$4000,3,0) -> True Shop Robinson Sri Saman | AB12: =VLOOKUP(B12,Sheet1!A$4:F$4000,4,0) -> BMA I - North West | AC12: =VLOOKUP(B12,Sheet1!A$4:F$4000,6,0) -> BMA
A13: RC-180-202608054 | B13: True Shop Future Park Rangsit Fl.2 | C13: POS | D13: 17/8/2026 | E13: 0.0 | F13: 0 | G13: 551.4 | H13: 38.6 | I13: 590 | J13: 01073421 | K13: สำเร็จ | L13: True Shop Future Park Rangsit Fl.2 | M13: ชำระครบ | O13: SCB | P13: 590 | Q13: 17/8/2026 19:42 | R13: 2IPH173SCM013 | S13: Sheep Clear Magsafe - iPhone 17 Pro Max | T13: 1 | U13: 690 | V13: 100.0 | W13: 590 | Y13: Sheep Clear | Z13: =VLOOKUP(B13,Sheet1!A$4:F$4000,2,0) -> 80101340 | AA13: =VLOOKUP(B13,Sheet1!A$4:F$4000,3,0) -> True Shop Future Park Rangsit Fl.2 | AB13: =VLOOKUP(B13,Sheet1!A$4:F$4000,4,0) -> BMA III - North East | AC13: =VLOOKUP(B13,Sheet1!A$4:F$4000,6,0) -> BMA
A14: RC-61-202608026 | B14: True Shop Central Rama 2 | C14: POS | D14: 17/8/2026 | E14: 0.0 | F14: 0 | G14: 831.78 | H14: 58.22 | I14: 890 | J14: 01046311 | K14: สำเร็จ | L14: True Shop Central Rama 2 | M14: ชำระครบ | O14: BBL | P14: 890 | Q14: 17/8/2026 19:31 | R14: 5IPH172IMM504 | S14: iPhone 17 Pro Magsafe - Stitch Aloha | T14: 1 | U14: 990 | V14: 100.0 | W14: 890 | Y14: Disney x Sheep | Z14: =VLOOKUP(B14,Sheet1!A$4:F$4000,2,0) -> 80100565 | AA14: =VLOOKUP(B14,Sheet1!A$4:F$4000,3,0) -> True Shop Central Rama 2 | AB14: =VLOOKUP(B14,Sheet1!A$4:F$4000,4,0) -> BMA II - South West | AC14: =VLOOKUP(B14,Sheet1!A$4:F$4000,6,0) -> BMA
A15: RC-143-202608023 | B15: True Shop Central Krabi | C15: POS | D15: 17/8/2026 | E15: 0.0 | F15: 0 | G15: 644.86 | H15: 45.14 | I15: 690 | J15: 12809505 | K15: สำเร็จ | L15: True Shop Central Krabi | M15: ชำระครบ | O15: SCB | P15: 690 | Q15: 17/8/2026 19:25 | R15: 2IPH170SCM558 | S15: Sheep Canvas Clear Matte Blue - iPhone 17 | T15: 1 | U15: 690 | V15: 0.0 | W15: 690 | Y15: Sheep Clear | Z15: =VLOOKUP(B15,Sheet1!A$4:F$4000,2,0) -> 80101647 | AA15: =VLOOKUP(B15,Sheet1!A$4:F$4000,3,0) -> True Shop Central Krabi | AB15: =VLOOKUP(B15,Sheet1!A$4:F$4000,4,0) -> UPC - Upper South | AC15: =VLOOKUP(B15,Sheet1!A$4:F$4000,6,0) -> UPC II
A16: RC-203-202608022 | B16: True Shop Central Chiangrai | C16: POS | D16: 17/8/2026 | E16: 0.0 | F16: 0 | G16: 635.51 | H16: 44.49 | I16: 680 | K16: สำเร็จ | L16: True Shop Central Chiangrai | M16: ชำระครบ | O16: KBANK | P16: 680 | Q16: 17/8/2026 19:00 | R16: 2SIP171SPC013 | S16: Sheep Screen Protector Clear - iPhone Air | T16: 1 | U16: 490 | V16: 0.0 | W16: 490 | Y16: Screen Protector | Z16: =VLOOKUP(B16,Sheet1!A$4:F$4000,2,0) -> 80100621 | AA16: =VLOOKUP(B16,Sheet1!A$4:F$4000,3,0) -> True Shop Central Chiangrai | AB16: =VLOOKUP(B16,Sheet1!A$4:F$4000,4,0) -> UPC - Upper North | AC16: =VLOOKUP(B16,Sheet1!A$4:F$4000,6,0) -> UPC I
A17: RC-203-202608022 | B17: True Shop Central Chiangrai | C17: POS | D17: 17/8/2026 | K17: สำเร็จ | L17: True Shop Central Chiangrai | M17: ชำระครบ | R17: 2SCP171BCG013 | S17: Sheep Bullet Camera Glass Clear iPhone Air | T17: 1 | U17: 190 | V17: 0.0 | W17: 190 | Y17: Screen Protector | Z17: =VLOOKUP(B17,Sheet1!A$4:F$4000,2,0) -> 80100621 | AA17: =VLOOKUP(B17,Sheet1!A$4:F$4000,3,0) -> True Shop Central Chiangrai | AB17: =VLOOKUP(B17,Sheet1!A$4:F$4000,4,0) -> UPC - Upper North | AC17: =VLOOKUP(B17,Sheet1!A$4:F$4000,6,0) -> UPC I
A18: RC-179-202608053 | B18: True Shop Megabangna | C18: POS | D18: 17/8/2026 | E18: 0.0 | F18: 0 | G18: 551.4 | H18: 38.6 | I18: 590 | J18: 01056426 | K18: สำเร็จ | L18: True Shop Mega Bangna | M18: ชำระครบ | O18: KBANK | P18: 590 | Q18: 17/8/2026 18:57 | R18: 2IPH172SCM013 | S18: Sheep Clear Magsafe - iPhone 17 Pro | T18: 1 | U18: 690 | V18: 100.0 | W18: 590 | Y18: Sheep Clear | Z18: =VLOOKUP(B18,Sheet1!A$4:F$4000,2,0) -> 80101070 | AA18: =VLOOKUP(B18,Sheet1!A$4:F$4000,3,0) -> True Shop Mega Bangna | AB18: =VLOOKUP(B18,Sheet1!A$4:F$4000,4,0) -> BMA IV - South East | AC18: =VLOOKUP(B18,Sheet1!A$4:F$4000,6,0) -> BMA
A19: RC-141-202608028 | B19: True Shop The mall Bangkapi | C19: POS | D19: 17/8/2026 | E19: 0.0 | F19: 0 | G19: 915.89 | H19: 64.11 | I19: 980 | J19: 010L6088 | K19: สำเร็จ | L19: True Shop The Mall Bangkapi | M19: ชำระครบ | O19: KBANK | P19: 980 | Q19: 17/8/2026 18:56 | R19: 2IPH172SCM013 | S19: Sheep Clear Magsafe - iPhone 17 Pro | T19: 1 | U19: 690 | V19: 63.89 | W19: 626.11 | Y19: Sheep Clear | Z19: =VLOOKUP(B19,Sheet1!A$4:F$4000,2,0) -> 80100481 | AA19: =VLOOKUP(B19,Sheet1!A$4:F$4000,3,0) -> True Shop The Mall Bangkapi | AB19: =VLOOKUP(B19,Sheet1!A$4:F$4000,4,0) -> BMA IV - South East | AC19: =VLOOKUP(B19,Sheet1!A$4:F$4000,6,0) -> BMA
A20: RC-141-202608028 | B20: True Shop The mall Bangkapi | C20: POS | D20: 17/8/2026 | J20: 010L6088 | K20: สำเร็จ | L20: True Shop The Mall Bangkapi | M20: ชำระครบ | R20: 2SCP172BCG004 | S20: Sheep Bullet Camera Glass iPhone 17 Pro /17 Pro Max - Blue | T20: 1 | U20: 390 | V20: 36.11 | W20: 353.89 | Y20: Screen Protector | Z20: =VLOOKUP(B20,Sheet1!A$4:F$4000,2,0) -> 80100481 | AA20: =VLOOKUP(B20,Sheet1!A$4:F$4000,3,0) -> True Shop The Mall Bangkapi | AB20: =VLOOKUP(B20,Sheet1!A$4:F$4000,4,0) -> BMA IV - South East | AC20: =VLOOKUP(B20,Sheet1!A$4:F$4000,6,0) -> BMA
A21: RC-85-202608009 | B21: True Shop Robinson Ratchapruek | C21: POS | D21: 17/8/2026 | E21: 0.0 | F21: 0 | G21: 831.78 | H21: 58.22 | I21: 890 | J21: 010H9703 | K21: สำเร็จ | L21: True Shop Robinson Ratchapruek | M21: ชำระครบ | O21: KBANK | P21: 890 | Q21: 17/8/2026 18:47 | R21: 4IPH173IMM516 | S21: Sheep Canvas 17 Pro Max - Cinnamoroll | T21: 1 | U21: 990 | V21: 100.0 | W21: 890 | Y21: Sanrio x Sheep | Z21: =VLOOKUP(B21,Sheet1!A$4:F$4000,2,0) -> 80101584 | AA21: =VLOOKUP(B21,Sheet1!A$4:F$4000,3,0) -> True Shop Robinson Ratchapruek | AB21: =VLOOKUP(B21,Sheet1!A$4:F$4000,4,0) -> BMA I - North West | AC21: =VLOOKUP(B21,Sheet1!A$4:F$4000,6,0) -> BMA
A22: RC-203-202608021 | B22: True Shop Central Chiangrai | C22: POS | D22: 17/8/2026 | E22: 0.0 | F22: 0 | G22: 644.86 | H22: 45.14 | I22: 690 | K22: สำเร็จ | L22: True Shop Central Chiangrai | M22: ชำระครบ | O22: KBANK | P22: 690 | Q22: 17/8/2026 18:46 | R22: 2IPH170SCM555 | S22: Sheep Canvas Clear Matte Black - iPhone 17 | T22: 1 | U22: 690 | V22: 0.0 | W22: 690 | Y22: Sheep Clear | Z22: =VLOOKUP(B22,Sheet1!A$4:F$4000,2,0) -> 80100621 | AA22: =VLOOKUP(B22,Sheet1!A$4:F$4000,3,0) -> True Shop Central Chiangrai | AB22: =VLOOKUP(B22,Sheet1!A$4:F$4000,4,0) -> UPC - Upper North | AC22: =VLOOKUP(B22,Sheet1!A$4:F$4000,6,0) -> UPC I
A23: RC-208-202608040 | B23: True Shop Central Khonkaen | C23: POS | D23: 17/8/2026 | E23: 0.0 | F23: 0 | G23: 551.4 | H23: 38.6 | I23: 590 | J23: 12808459 | K23: สำเร็จ | L23: True Shop Central Khonkaen | M23: ชำระครบ | O23: KBANK | P23: 590 | Q23: 17/8/2026 18:43 | R23: 2IPH173SCM013 | S23: Sheep Clear Magsafe - iPhone 17 Pro Max | T23: 1 | U23: 690 | V23: 100.0 | W23: 590 | Y23: Sheep Clear | Z23: =VLOOKUP(B23,Sheet1!A$4:F$4000,2,0) -> 80101183 | AA23: =VLOOKUP(B23,Sheet1!A$4:F$4000,3,0) -> True Shop Central Khonkaen | AB23: =VLOOKUP(B23,Sheet1!A$4:F$4000,4,0) -> UPC - Upper Northeast | AC23: =VLOOKUP(B23,Sheet1!A$4:F$4000,6,0) -> UPC I
A24: RC-93-202608010 | B24: True Shop Robinson Mae Sot | C24: POS | D24: 17/8/2026 | E24: 0.0 | F24: 0 | G24: 644.86 | H24: 45.14 | I24: 690 | K24: สำเร็จ | L24: True Shop Robinson Mae Sot | M24: ชำระครบ | O24: KBANK | P24: 690 | Q24: 17/8/2026 18:37 | R24: 2IPH170SCM013 | S24: Sheep Clear Magsafe - iPhone 17 | T24: 1 | U24: 690 | V24: 0.0 | W24: 690 | Y24: Sheep Clear | Z24: =VLOOKUP(B24,Sheet1!A$4:F$4000,2,0) -> 80101306 | AA24: =VLOOKUP(B24,Sheet1!A$4:F$4000,3,0) -> True Shop Robinson Mae Sot | AB24: =VLOOKUP(B24,Sheet1!A$4:F$4000,4,0) -> UPC - Lower North | AC24: =VLOOKUP(B24,Sheet1!A$4:F$4000,6,0) -> UPC I
A25: RC-105-202608033 | B25: True Shop Lotus's Ranong | C25: POS | D25: 17/8/2026 | E25: 0.0 | F25: 0 | G25: 692.52 | H25: 48.48 | I25: 741 | J25: 010J1044 | K25: สำเร็จ | L25: True Shop Lotus's Ranong | M25: ชำระครบ | O25: TTB | P25: 741 | Q25: 17/8/2026 18:25 | R25: 5ACC999MWL528 | S25: Magsafe Wallet - Mickey Iconic | T25: 2 | U25: 390 | V25: 19.5 | W25: 741 | Y25: Disney x Sheep | Z25: =VLOOKUP(B25,Sheet1!A$4:F$4000,2,0) -> 80100822 | AA25: =VLOOKUP(B25,Sheet1!A$4:F$4000,3,0) -> True Shop Lotus's Ranong | AB25: =VLOOKUP(B25,Sheet1!A$4:F$4000,4,0) -> UPC - Upper South | AC25: =VLOOKUP(B25,Sheet1!A$4:F$4000,6,0) -> UPC II
A26: RC-125-202608210 | B26: TRUE - Central Rama 9 | C26: POS | D26: 17/8/2026 | E26: 0.0 | F26: 0 | G26: 925.23 | H26: 64.77 | I26: 990 | J26: n | K26: สำเร็จ | L26: True Shop Central Rama 9 | M26: ชำระครบ | O26: KBANK | P26: 990 | Q26: 17/8/2026 18:24 | R26: 9IPH163IMM514 | S26: iPhone 16 Pro Max Magsafe - Monchhichi | T26: 1 | U26: 990 | V26: 0.0 | W26: 990 | Y26: Monchhichi TH | Z26: =VLOOKUP(B26,Sheet1!A$4:F$4000,2,0) -> 80100623 | AA26: =VLOOKUP(B26,Sheet1!A$4:F$4000,3,0) -> True Shop Central Rama 9 | AB26: =VLOOKUP(B26,Sheet1!A$4:F$4000,4,0) -> BMA V - Central | AC26: =VLOOKUP(B26,Sheet1!A$4:F$4000,6,0) -> BMA
A27: RC-125-202608209 | B27: TRUE - Central Rama 9 | C27: POS | D27: 17/8/2026 | E27: 0.00 | F27: 0 | G27: 364.49 | H27: 25.51 | I27: 390 | J27: b RC-125-202608209 TF-202608891 Wallet Lady ศุภะภัสสร เวศยาสิรินทร์ 97/59 ชั้น 8 อาคาร B อาคารชุดลุมพินีเพลส พระราม 9 ถ.พระราม 9 แขวงห้วยขวาง เขตห้วยขวาง กรุงเทพมหานคร 10310 โทร.0954387981 | K27: สำเร็จ | L27: True Shop Central Rama 9 | M27: ชำระครบ | O27: KBANK | P27: 390 | Q27: 17/8/2026 18:20 | R27: TRUE0390 | S27: Pre-Order TR - 390 | T27: 1 | U27: 0 | V27: 0.00 | W27: 0 | Y27: TRUE ONLY | Z27: =VLOOKUP(B27,Sheet1!A$4:F$4000,2,0) -> 80100623 | AA27: =VLOOKUP(B27,Sheet1!A$4:F$4000,3,0) -> True Shop Central Rama 9 | AB27: =VLOOKUP(B27,Sheet1!A$4:F$4000,4,0) -> BMA V - Central | AC27: =VLOOKUP(B27,Sheet1!A$4:F$4000,6,0) -> BMA
A28: RC-125-202608209 | B28: TRUE - Central Rama 9 | C28: POS | D28: 17/8/2026 | J28: b RC-125-202608209 TF-202608891 Wallet Lady ศุภะภัสสร เวศยาสิรินทร์ 97/59 ชั้น 8 อาคาร B อาคารชุดลุมพินีเพลส พระราม 9 ถ.พระราม 9 แขวงห้วยขวาง เขตห้วยขวาง กรุงเทพมหานคร 10310 โทร.0954387981 | K28: สำเร็จ | L28: True Shop Central Rama 9 | M28: ชำระครบ | R28: 5ACC999MWL420 | S28: Magsafe Wallet - Lady and the Tramp | T28: 1 | U28: 390 | W28: 390 | Y28: Disney x Sheep | Z28: =VLOOKUP(B28,Sheet1!A$4:F$4000,2,0) -> 80100623 | AA28: =VLOOKUP(B28,Sheet1!A$4:F$4000,3,0) -> True Shop Central Rama 9 | AB28: =VLOOKUP(B28,Sheet1!A$4:F$4000,4,0) -> BMA V - Central | AC28: =VLOOKUP(B28,Sheet1!A$4:F$4000,6,0) -> BMA
A29: RC-157-202608010 | B29: True Shop Central Airport Plaza Chiangmai | C29: POS | D29: 17/8/2026 | E29: 0.0 | F29: 0 | G29: 831.78 | H29: 58.22 | I29: 890 | K29: สำเร็จ | L29: True Shop Central Airport Plaza Chiangmai | M29: ชำระครบ | O29: KBANK | P29: 890 | Q29: 17/8/2026 18:20 | R29: 5SSC506IMM526 | S29: Sheep Canvas S26 Ultra - Mickey Mouse | T29: 1 | U29: 990 | V29: 100.0 | W29: 890 | Y29: Disney x Sheep | Z29: =VLOOKUP(B29,Sheet1!A$4:F$4000,2,0) -> 80101067 | AA29: =VLOOKUP(B29,Sheet1!A$4:F$4000,3,0) -> True Shop Central Airport Plaza Chiangmai | AB29: =VLOOKUP(B29,Sheet1!A$4:F$4000,4,0) -> UPC - Upper North | AC29: =VLOOKUP(B29,Sheet1!A$4:F$4000,6,0) -> UPC I
A30: RC-169-202608050 | B30: True Shop Central Westgate | C30: POS | D30: 17/8/2026 | E30: 0.0 | F30: 0 | G30: 831.78 | H30: 58.22 | I30: 890 | J30: 010F8555 | K30: สำเร็จ | L30: True Shop Central West Gate | M30: ชำระครบ | O30: KBANK | P30: 890 | Q30: 17/8/2026 18:15 | R30: 9SSC506IMM515 | S30: Sheep Canvas S26 Ultra - Kawaii Monchhichi | T30: 1 | U30: 990 | V30: 100.0 | W30: 890 | Y30: Monchhichi TH | Z30: =VLOOKUP(B30,Sheet1!A$4:F$4000,2,0) -> 80101185 | AA30: =VLOOKUP(B30,Sheet1!A$4:F$4000,3,0) -> True Shop Central West Gate | AB30: =VLOOKUP(B30,Sheet1!A$4:F$4000,4,0) -> BMA I - North West | AC30: =VLOOKUP(B30,Sheet1!A$4:F$4000,6,0) -> BMA
A31: RC-95-202608005 | B31: True Shop Lotus's Thaluang Phichit | C31: POS | D31: 17/8/2026 | E31: 0.0 | F31: 0 | G31: 457.94 | H31: 32.06 | I31: 490 | J31: 010J5766 | K31: สำเร็จ | L31: True Shop Lotus's Thaluang Phichit | M31: ชำระครบ | O31: KBANK | P31: 490 | Q31: 17/8/2026 18:07 | R31: 2SIP170SPC013 | S31: Sheep Screen Protector Clear - iPhone 17 / 16 Pro | T31: 1 | U31: 490 | V31: 0.0 | W31: 490 | Y31: Screen Protector | Z31: =VLOOKUP(B31,Sheet1!A$4:F$4000,2,0) -> 80100782 | AA31: =VLOOKUP(B31,Sheet1!A$4:F$4000,3,0) -> True Shop Lotus's Thaluang Phichit | AB31: =VLOOKUP(B31,Sheet1!A$4:F$4000,4,0) -> UPC - Lower North | AC31: =VLOOKUP(B31,Sheet1!A$4:F$4000,6,0) -> UPC I
A32: RC-145-202608023 | B32: True Shop Seacon Bangkae | C32: POS | D32: 17/8/2026 | E32: 0.0 | F32: 0 | G32: 831.78 | H32: 58.22 | I32: 890 | J32: 01056133 | K32: สำเร็จ | L32: True Shop Seacon Bangkae | M32: ชำระครบ | O32: KBANK | P32: 890 | Q32: 17/8/2026 18:00 | R32: 4IPH173IMM516 | S32: Sheep Canvas 17 Pro Max - Cinnamoroll | T32: 1 | U32: 990 | V32: 100.0 | W32: 890 | Y32: Sanrio x Sheep | Z32: =VLOOKUP(B32,Sheet1!A$4:F$4000,2,0) -> 80100928 | AA32: =VLOOKUP(B32,Sheet1!A$4:F$4000,3,0) -> True Shop Seacon Bangkae | AB32: =VLOOKUP(B32,Sheet1!A$4:F$4000,4,0) -> BMA II - South West | AC32: =VLOOKUP(B32,Sheet1!A$4:F$4000,6,0) -> BMA
A33: RC-143-202608022 | B33: True Shop Central Krabi | C33: POS | D33: 17/8/2026 | E33: 0.0 | F33: 0 | G33: 364.49 | H33: 25.51 | I33: 390 | J33: 01081894 | K33: สำเร็จ | L33: True Shop Central Krabi | M33: ชำระครบ | O33: TTB | P33: 390 | Q33: 17/8/2026 17:58 | R33: 2SCP172BCG090 | S33: Sheep Bullet Camera Glass iPhone 17 Pro /17 Pro Max - Silver | T33: 1 | U33: 390 | V33: 0.0 | W33: 390 | Y33: Screen Protector | Z33: =VLOOKUP(B33,Sheet1!A$4:F$4000,2,0) -> 80101647 | AA33: =VLOOKUP(B33,Sheet1!A$4:F$4000,3,0) -> True Shop Central Krabi | AB33: =VLOOKUP(B33,Sheet1!A$4:F$4000,4,0) -> UPC - Upper South | AC33: =VLOOKUP(B33,Sheet1!A$4:F$4000,6,0) -> UPC II
A34: RC-25-202608030 | B34: True Shop Central Plaza Rayong | C34: POS | D34: 17/8/2026 | E34: 0.0 | F34: 0 | G34: 831.78 | H34: 58.22 | I34: 890 | J34: 01052664 | K34: สำเร็จ | L34: True Shop Central Plaza Rayong | M34: ชำระครบ | O34: KBANK | P34: 890 | Q34: 17/8/2026 17:50 | R34: 9SSC506IMM507 | S34: Sheep Canvas S26 Ultra - Momorei Rico | T34: 1 | U34: 990 | V34: 100.0 | W34: 890 | Y34: Momorei | Z34: =VLOOKUP(B34,Sheet1!A$4:F$4000,2,0) -> 80100625 | AA34: =VLOOKUP(B34,Sheet1!A$4:F$4000,3,0) -> True Shop Central Plaza Rayong | AB34: =VLOOKUP(B34,Sheet1!A$4:F$4000,4,0) -> UPC - East | AC34: =VLOOKUP(B34,Sheet1!A$4:F$4000,6,0) -> UPC II
A35: RC-136-202608038 | B35: True Shop Seacon Square 2 | C35: POS | D35: 17/8/2026 | E35: 0.0 | F35: 0 | G35: 925.23 | H35: 64.77 | I35: 990 | J35: 01075608 | K35: สำเร็จ | L35: True Shop Seacon Square 2 | M35: ชำระครบ | O35: TTB | P35: 990 | Q35: 17/8/2026 18:14 | R35: 9IPH173IMM507 | S35: iPhone 17 Pro Max Magsafe - Momorei Rico | T35: 1 | U35: 990 | V35: 0.0 | W35: 990 | Y35: Momorei | Z35: =VLOOKUP(B35,Sheet1!A$4:F$4000,2,0) -> 80101071 | AA35: =VLOOKUP(B35,Sheet1!A$4:F$4000,3,0) -> True Shop Seacon Square 2 | AB35: =VLOOKUP(B35,Sheet1!A$4:F$4000,4,0) -> BMA IV - South East | AC35: =VLOOKUP(B35,Sheet1!A$4:F$4000,6,0) -> BMA
A36: RC-156-202608034 | B36: True Shop The mall Bangkae | C36: POS | D36: 17/8/2026 | E36: 0.0 | F36: 0 | G36: 326.17 | H36: 22.83 | I36: 349 | J36: 01040851 | K36: สำเร็จ | L36: True Shop The Mall Bangkae 2Fl. | M36: ชำระครบ | O36: KBANK | P36: 349 | Q36: 17/8/2026 17:50 | R36: 4PHC999CHR516 | S36: Sheep Phone Charm - Cinnamoroll | T36: 1 | U36: 349 | V36: 0.0 | W36: 349 | Y36: Sanrio x Sheep | Z36: =VLOOKUP(B36,Sheet1!A$4:F$4000,2,0) -> 80100484 | AA36: =VLOOKUP(B36,Sheet1!A$4:F$4000,3,0) -> True Shop The Mall Bangkae 2Fl. | AB36: =VLOOKUP(B36,Sheet1!A$4:F$4000,4,0) -> BMA II - South West | AC36: =VLOOKUP(B36,Sheet1!A$4:F$4000,6,0) -> BMA
A37: RC-141-202608027 | B37: True Shop The mall Bangkapi | C37: POS | D37: 17/8/2026 | E37: 0.0 | F37: 0 | G37: 644.86 | H37: 45.14 | I37: 690 | J37: 01032997 | K37: สำเร็จ | L37: True Shop The Mall Bangkapi | M37: ชำระครบ | O37: KBANK | P37: 690 | Q37: 17/8/2026 17:47 | R37: 2IPH173SCM004 | S37: Sheep Canvas Clear Blue - iPhone 17 Pro Max | T37: 1 | U37: 690 | V37: 0.0 | W37: 690 | Y37: Sheep Clear | Z37: =VLOOKUP(B37,Sheet1!A$4:F$4000,2,0) -> 80100481 | AA37: =VLOOKUP(B37,Sheet1!A$4:F$4000,3,0) -> True Shop The Mall Bangkapi | AB37: =VLOOKUP(B37,Sheet1!A$4:F$4000,4,0) -> BMA IV - South East | AC37: =VLOOKUP(B37,Sheet1!A$4:F$4000,6,0) -> BMA
A38: RC-143-202608021 | B38: True Shop Central Krabi | C38: POS | D38: 17/8/2026 | E38: 0.0 | F38: 0 | G38: 644.86 | H38: 45.14 | I38: 690 | K38: สำเร็จ | L38: True Shop Central Krabi | M38: ชำระครบ | O38: TTB | P38: 690 | Q38: 17/8/2026 17:38 | R38: 2IPH172SCM013 | S38: Sheep Clear Magsafe - iPhone 17 Pro | T38: 1 | U38: 690 | V38: 0.0 | W38: 690 | Y38: Sheep Clear | Z38: =VLOOKUP(B38,Sheet1!A$4:F$4000,2,0) -> 80101647 | AA38: =VLOOKUP(B38,Sheet1!A$4:F$4000,3,0) -> True Shop Central Krabi | AB38: =VLOOKUP(B38,Sheet1!A$4:F$4000,4,0) -> UPC - Upper South | AC38: =VLOOKUP(B38,Sheet1!A$4:F$4000,6,0) -> UPC II
A39: RC-143-202608020 | B39: True Shop Central Krabi | C39: POS | D39: 17/8/2026 | E39: 0.0 | F39: 0 | G39: 551.4 | H39: 38.6 | I39: 590 | J39: 12809505 | K39: สำเร็จ | L39: True Shop Central Krabi | M39: ชำระครบ | O39: TTB | P39: 590 | Q39: 17/8/2026 17:35 | R39: 2IPH173SCM013 | S39: Sheep Clear Magsafe - iPhone 17 Pro Max | T39: 1 | U39: 690 | V39: 100.0 | W39: 590 | Y39: Sheep Clear | Z39: =VLOOKUP(B39,Sheet1!A$4:F$4000,2,0) -> 80101647 | AA39: =VLOOKUP(B39,Sheet1!A$4:F$4000,3,0) -> True Shop Central Krabi | AB39: =VLOOKUP(B39,Sheet1!A$4:F$4000,4,0) -> UPC - Upper South | AC39: =VLOOKUP(B39,Sheet1!A$4:F$4000,6,0) -> UPC II
A40: RC-170-202608037 | B40: True Shop Central Plaza Nakhon Ratchasima | C40: POS | D40: 17/8/2026 | E40: 0.0 | F40: 0 | G40: 271.03 | H40: 18.97 | I40: 290 | J40: 010L6270 | K40: สำเร็จ | L40: True Shop Central Plaza Nakhon Ratchasima | M40: ชำระครบ | O40: KBANK | P40: 290 | Q40: 17/8/2026 17:22 | R40: 2SCP170BCG033 | S40: Sheep Bullet Camera Glass iPhone 17 - Light Blue | T40: 1 | U40: 290 | V40: 0.0 | W40: 290 | Y40: Screen Protector | Z40: =VLOOKUP(B40,Sheet1!A$4:F$4000,2,0) -> 80101119 | AA40: =VLOOKUP(B40,Sheet1!A$4:F$4000,3,0) -> True Shop Central Plaza Nakhon Ratchasima | AB40: =VLOOKUP(B40,Sheet1!A$4:F$4000,4,0) -> UPC - Lower Northeast | AC40: =VLOOKUP(B40,Sheet1!A$4:F$4000,6,0) -> UPC I
...

Sheet Sheet1
B3: Shop Name | C3: Shop Name | D3: AREA | E3: Type
A4: True Shop Central Chaengwattana | B4: 80101182 | C4: True Shop Central Chaengwattana | D4: BMA I - North West | E4: Wall | F4: BMA
A5: True Shop Central Westgate | B5: 80101185 | C5: True Shop Central West Gate | D5: BMA I - North West | E5: Wall | F5: BMA
A6: True Shop The mall Bangkae | B6: 80100484 | C6: True Shop The Mall Bangkae 2Fl. | D6: BMA II - South West | E6: Wall | F6: BMA
A7: TRUE - Fashion Island | B7: 80100925 | C7: True Shop Fashion Island | D7: BMA III - North East | E7: SIS | F7: BMA
A8: True Shop The mall Bangkapi | B8: 80100481 | C8: True Shop The Mall Bangkapi | D8: BMA IV - South East | E8: Wall | F8: BMA
A9: True Shop Seacon square | B9: 80101065 | C9: True Shop Seacon Square | D9: BMA IV - South East | E9: Wall | F9: BMA
A10: True Shop Megabangna | B10: 80101070 | C10: True Shop Mega Bangna | D10: BMA IV - South East | E10: Wall | F10: BMA
A11: True Shop Central Rama9 4Fl. | B11: 80100622 | C11: True Shop Central Rama 9 4Fl. | D11: BMA V - Central | E11: Wall | F11: BMA
A12: TRUE - Central Rama 9 | B12: 80100623 | C12: True Shop Central Rama 9 | D12: BMA V - Central | E12: SIS | F12: BMA
A13: True Shop Central World 4Fl. | B13: 80100836 | C13: True Shop Central World 4Fl. | D13: BMA V - Central | E13: Wall | F13: BMA
A14: True Shop Central East Ville | B14: 80101186 | C14: True Shop Central Festival East Ville | D14: BMA V - Central | E14: Wall | F14: BMA
A15: True Shop Emquartier | B15: 80101221 | C15: True Shop Emquartier | D15: BMA V - Central | E15: Wall | F15: BMA
... A71: True Shop Chamchuri Square 1 | B71: 80101363 | C71: True shop Chamchuri Square 1 | D71: BMA V - Central | E71: Wall | F71: BMA
A72: True Shop Robinson Ratchapruek | B72: 80101584 | C72: True Shop Robinson Ratchapruek | D72: BMA I - North West | F72: BMA
A73: True Shop Wongsawang Town Center | B73: 80101180 | C73: True Shop Wongsawang Town Center | D73: BMA I - North West | F73: BMA
A74: True Shop Big C Sainoi Nonthaburi | B74: 80101218 | C74: True Shop Big C Sainoi Nonthaburi | D74: BMA I - North West | F74: BMA
A75: True Shop Big C Chaengwattana | B75: 80101271 | C75: True Shop Big C Chaengwattana | D75: BMA I - North West | F75: BMA
A76: True Shop Central Plaza Ramindra 1FL. | B76: 80101264 | C76: True Shop Central Plaza Ramindra 1FL. | D76: BMA I - North West | F76: BMA
A77: True Shop Lotus's Sukhapibal 3 | B77: 80101123 | C77: True Shop Lotus's Sukhapibal 3 | D77: BMA III - North East | F77: BMA
A78: True Shop iPlace Latkrabang | B78: 80101350 | C78: True Shop iPlace Latkrabang | D78: BMA III - North East | F78: BMA
A79: True Shop Paradise Park Srinakarin | B79: 80101296 | C79: True Shop Paradise Park Srinakarin | D79: BMA IV - South East | F79: BMA
A80: True Shop Imperial World Samrong | B80: 80101418 | C80: True Shop Imperial World Samrong | D80: BMA IV - South East | F80: BMA
A81: True Shop Robinson Lopburi | B81: 80101307 | C81: True Shop Robinson Lopburi | D81: UPC - Central | F81: UPC II
A82: True Shop The Walk Nakornsawan | B82: 80100763 | C82: True Shop The Walk Nakornsawan | D82: UPC - Central | F82: UPC II
A83: True Move Shop Taweekit Complex Saraburi | B83: 80100841 | C83: True Move Shop Taweekit Complex Saraburi | D83: UPC - Central | F83: UPC II
... A112: True Shop Seacon Square 2 | B112: 80101071 | C112: True Shop Seacon Square 2 | D112: BMA IV - South East | F112: BMA
A113: True Shop Central Krabi | B113: 80101647 | C113: True Shop Central Krabi | D113: UPC - Upper South | E113: Wall | F113: UPC II
A114: True Shop Lotus's Bangna-trad | B114: 80101632 | C114: True Shop Lotus's Bangna-trad | D114: BMA IV - South East | F114: BMA
A115: True Shop Central Northville | B115: 80101713 | C115: True Shop Central Northville | D115: BMA I - North West | E115: Wall | F115: BMA
A116: True Shop Central Plaza Chaengwattana (D) | B116: 80101702 | C116: True Shop Central Plaza Chaengwattana (D) | D116: BMA I - North West | F116: BMA
A117: True Shop Future Park Rangsit (2 nd.) (D) | B117: 80101707 | C117: True Shop Future Park Rangsit (2 nd.) (D) | D117: BMA III - North East | F117: BMA
A118: True Shop Future Park Rangsit (G Fl.) (D) | B118: 80101708 | C118: True Shop Future Park Rangsit (G Fl.) (D) | D118: BMA III - North East | F118: BMA
A119: True Shop Mega Bangna (D) | B119: 80101709 | C119: True Shop Mega Bangna (D) | D119: BMA IV - South East | F119: BMA
A120: True Shop Ayutthaya (D) | B120: 80101691 | C120: True Shop Ayutthaya (D) | D120: UPC - Central | F120: UPC II
A121: True Shop Central Rayong (D) | B121: 80101695 | C121: True Shop Central Rayong (D) | D121: UPC - East | F121: UPC II
A122: True Shop Central Festival Pattaya (D) | B122: 80101700 | C122: True Shop Central Festival Pattaya (D) | D122: UPC - East | F122: UPC II
A123: True Shop Central Plaza Khon Kaen (D) | B123: 80101703 | C123: True Shop Central Plaza Khon Kaen (D) | D123: UPC - Upper Northeast | F123: UPC I
A124: True Shop Central Plaza Mahachai (D) | B124: 80101693 | C124: True Shop Central Plaza Mahachai (D) | D124: UPC - West | F124: UPC II
A125: True Shop Central Salaya (D) | B125: 80101696 | C125: True Shop Central Salaya (D) | D125: UPC - West | F125: UPC II
...

Sheet Performance Staff
A1: Id Staff | B1: Staff Name | C1: Emp Type | D1: Shop code | E1: Shop Name | F1: Area | G1: Shop Type | H1: Regional | I1: Target Net Amounr | J1: Ach | K1: %Ach | L1: Target QTY | M1: Ach | N1: %Ach
A2: 01056670 | B2: จิราภรณ์ ทองชัย | C2: Ret_chpn_1 | D2: 80100477 | E2: True Shop Central Ladprao | F2: BMA I - North West | G2: Matching | H2: BMA | I2: 455.62126 | J2: =IFERROR(VLOOKUP(A2,'PV Sheep mail'!M$4:O$140000,3,0),0) -> 0 | K2: =J2/I2 -> 0 | L2: 0.60550459 | M2: =IFERROR(VLOOKUP(A2,'PV Sheep mail'!M$4:O$140000,2,0),0) -> 0 | N2: =M2/L2 -> 0
A3: 01091825 | B3: ณัฐวนัส ชูมณี | C3: Ret_chpn_1 | D3: 80100477 | E3: True Shop Central Ladprao | F3: BMA I - North West | G3: Matching | H3: BMA | I3: 455.62126 | J3: =IFERROR(VLOOKUP(A3,'PV Sheep mail'!M$4:O$140000,3,0),0) -> 0 | K3: =J3/I3 -> 0 | L3: 0.60550459 | M3: =IFERROR(VLOOKUP(A3,'PV Sheep mail'!M$4:O$140000,2,0),0) -> 0 | N3: =M3/L3 -> 0
A4: 01075126 | B4: ณัฐิกา เหลือนาง | C4: Ret_chpn_1 | D4: 80100477 | E4: True Shop Central Ladprao | F4: BMA I - North West | G4: Matching | H4: BMA | I4: 455.62126 | J4: =IFERROR(VLOOKUP(A4,'PV Sheep mail'!M$4:O$140000,3,0),0) -> 0 | K4: =J4/I4 -> 0 | L4: 0.60550459 | M4: =IFERROR(VLOOKUP(A4,'PV Sheep mail'!M$4:O$140000,2,0),0) -> 0 | N4: =M4/L4 -> 0
A5: 01069687 | B5: ทรงวุฒิ เฟื่องเกษม | C5: Ret_chpn_1 | D5: 80100477 | E5: True Shop Central Ladprao | F5: BMA I - North West | G5: Matching | H5: BMA | I5: 455.62126 | J5: =IFERROR(VLOOKUP(A5,'PV Sheep mail'!M$4:O$140000,3,0),0) -> 0 | K5: =J5/I5 -> 0 | L5: 0.60550459 | M5: =IFERROR(VLOOKUP(A5,'PV Sheep mail'!M$4:O$140000,2,0),0) -> 0 | N5: =M5/L5 -> 0
A6: 01092138 | B6: พนิดา ณรงค์ชัย | C6: Ret_chpn_1 | D6: 80100477 | E6: True Shop Central Ladprao | F6: BMA I - North West | G6: Matching | H6: BMA | I6: 455.62126 | J6: =IFERROR(VLOOKUP(A6,'PV Sheep mail'!M$4:O$140000,3,0),0) -> 0 | K6: =J6/I6 -> 0 | L6: 0.60550459 | M6: =IFERROR(VLOOKUP(A6,'PV Sheep mail'!M$4:O$140000,2,0),0) -> 0 | N6: =M6/L6 -> 0
A7: 12808834 | B7: พันธุ์รักษ์ เกตุโรจน์ | C7: Ret_chpn_1 | D7: 80100477 | E7: True Shop Central Ladprao | F7: BMA I - North West | G7: Matching | H7: BMA | I7: 455.62126 | J7: =IFERROR(VLOOKUP(A7,'PV Sheep mail'!M$4:O$140000,3,0),0) -> 0 | K7: =J7/I7 -> 0 | L7: 0.60550459 | M7: =IFERROR(VLOOKUP(A7,'PV Sheep mail'!M$4:O$140000,2,0),0) -> 0 | N7: =M7/L7 -> 0
A8: 01049964 | B8: ไพลิน จันทร์สมดี | C8: Ret_chpn_1 | D8: 80100477 | E8: True Shop Central Ladprao | F8: BMA I - North West | G8: Matching | H8: BMA | I8: 455.62126 | J8: =IFERROR(VLOOKUP(A8,'PV Sheep mail'!M$4:O$140000,3,0),0) -> 0 | K8: =J8/I8 -> 0 | L8: 0.60550459 | M8: =IFERROR(VLOOKUP(A8,'PV Sheep mail'!M$4:O$140000,2,0),0) -> 0 | N8: =M8/L8 -> 0
A9: 01069181 | B9: สุธาทิพย์ ไพโรจน์พิริยะกุล | C9: Ret_chpn_1 | D9: 80100477 | E9: True Shop Central Ladprao | F9: BMA I - North West | G9: Matching | H9: BMA | I9: 455.62126 | J9: =IFERROR(VLOOKUP(A9,'PV Sheep mail'!M$4:O$140000,3,0),0) -> 0 | K9: =J9/I9 -> 0 | L9: 0.60550459 | M9: =IFERROR(VLOOKUP(A9,'PV Sheep mail'!M$4:O$140000,2,0),0) -> 0 | N9: =M9/L9 -> 0
